---> Running application from Python script (app.py) ...
 * Serving Flask app 'app'
 * Debug mode: off
WARNING: This is a development server. Do not use it in a production deployment. Use a production WSGI server instead.
 * Running on all addresses (0.0.0.0)
 * Running on http://127.0.0.1:8080
 * Running on http://10.130.0.233:8080
Press CTRL+C to quit
[2024-12-22 23:29:58,617] ERROR in app: Exception on / [GET]
Traceback (most recent call last):
  File "/opt/app-root/lib64/python3.11/site-packages/sqlalchemy/engine/base.py", line 1967, in _exec_single_context
    self.dialect.do_execute(
  File "/opt/app-root/lib64/python3.11/site-packages/sqlalchemy/engine/default.py", line 941, in do_execute
    cursor.execute(statement, parameters)
sqlite3.OperationalError: no such table: article

The above exception was the direct cause of the following exception:

Traceback (most recent call last):
  File "/opt/app-root/lib64/python3.11/site-packages/flask/app.py", line 1511, in wsgi_app
    response = self.full_dispatch_request()
               ^^^^^^^^^^^^^^^^^^^^^^^^^^^^
  File "/opt/app-root/lib64/python3.11/site-packages/flask/app.py", line 919, in full_dispatch_request
    rv = self.handle_user_exception(e)
         ^^^^^^^^^^^^^^^^^^^^^^^^^^^^^
  File "/opt/app-root/lib64/python3.11/site-packages/flask/app.py", line 917, in full_dispatch_request
    rv = self.dispatch_request()
         ^^^^^^^^^^^^^^^^^^^^^^^
  File "/opt/app-root/lib64/python3.11/site-packages/flask/app.py", line 902, in dispatch_request
    return self.ensure_sync(self.view_functions[rule.endpoint])(**view_args)  # type: ignore[no-any-return]
           ^^^^^^^^^^^^^^^^^^^^^^^^^^^^^^^^^^^^^^^^^^^^^^^^^^^^^^^^^^^^^^^^^
  File "/opt/app-root/src/app.py", line 99, in home
    categories = get_unique_categories()
                 ^^^^^^^^^^^^^^^^^^^^^^^
  File "/opt/app-root/src/app.py", line 71, in get_unique_categories
    categories = db.session.query(Article.category).distinct().all()
                 ^^^^^^^^^^^^^^^^^^^^^^^^^^^^^^^^^^^^^^^^^^^^^^^^^^^
  File "/opt/app-root/lib64/python3.11/site-packages/sqlalchemy/orm/query.py", line 2673, in all
    return self._iter().all()  # type: ignore
           ^^^^^^^^^^^^
  File "/opt/app-root/lib64/python3.11/site-packages/sqlalchemy/orm/query.py", line 2827, in _iter
    result: Union[ScalarResult[_T], Result[_T]] = self.session.execute(
                                                  ^^^^^^^^^^^^^^^^^^^^^
  File "/opt/app-root/lib64/python3.11/site-packages/sqlalchemy/orm/session.py", line 2362, in execute
    return self._execute_internal(
           ^^^^^^^^^^^^^^^^^^^^^^^
  File "/opt/app-root/lib64/python3.11/site-packages/sqlalchemy/orm/session.py", line 2247, in _execute_internal
    result: Result[Any] = compile_state_cls.orm_execute_statement(
                          ^^^^^^^^^^^^^^^^^^^^^^^^^^^^^^^^^^^^^^^^
  File "/opt/app-root/lib64/python3.11/site-packages/sqlalchemy/orm/context.py", line 305, in orm_execute_statement
    result = conn.execute(
             ^^^^^^^^^^^^^
  File "/opt/app-root/lib64/python3.11/site-packages/sqlalchemy/engine/base.py", line 1418, in execute
    return meth(
           ^^^^^
  File "/opt/app-root/lib64/python3.11/site-packages/sqlalchemy/sql/elements.py", line 515, in _execute_on_connection
    return connection._execute_clauseelement(
           ^^^^^^^^^^^^^^^^^^^^^^^^^^^^^^^^^^
  File "/opt/app-root/lib64/python3.11/site-packages/sqlalchemy/engine/base.py", line 1640, in _execute_clauseelement
    ret = self._execute_context(
          ^^^^^^^^^^^^^^^^^^^^^^
  File "/opt/app-root/lib64/python3.11/site-packages/sqlalchemy/engine/base.py", line 1846, in _execute_context
    return self._exec_single_context(
           ^^^^^^^^^^^^^^^^^^^^^^^^^^
  File "/opt/app-root/lib64/python3.11/site-packages/sqlalchemy/engine/base.py", line 1986, in _exec_single_context
    self._handle_dbapi_exception(
  File "/opt/app-root/lib64/python3.11/site-packages/sqlalchemy/engine/base.py", line 2355, in _handle_dbapi_exception
    raise sqlalchemy_exception.with_traceback(exc_info[2]) from e
  File "/opt/app-root/lib64/python3.11/site-packages/sqlalchemy/engine/base.py", line 1967, in _exec_single_context
    self.dialect.do_execute(
  File "/opt/app-root/lib64/python3.11/site-packages/sqlalchemy/engine/default.py", line 941, in do_execute
    cursor.execute(statement, parameters)
sqlalchemy.exc.OperationalError: (sqlite3.OperationalError) no such table: article
[SQL: SELECT DISTINCT article.category AS article_category 
FROM article]
(Background on this error at: https://sqlalche.me/e/20/e3q8)
10.128.0.2 - - [22/Dec/2024 23:29:58] "GET / HTTP/1.1" 500 -
10.128.0.2 - - [22/Dec/2024 23:29:58] "GET /favicon.ico HTTP/1.1" 404 -
[2024-12-22 23:30:12,858] ERROR in app: Exception on / [GET]
Traceback (most recent call last):
  File "/opt/app-root/lib64/python3.11/site-packages/sqlalchemy/engine/base.py", line 1967, in _exec_single_context
    self.dialect.do_execute(
  File "/opt/app-root/lib64/python3.11/site-packages/sqlalchemy/engine/default.py", line 941, in do_execute
    cursor.execute(statement, parameters)
sqlite3.OperationalError: no such table: article

The above exception was the direct cause of the following exception:

Traceback (most recent call last):
  File "/opt/app-root/lib64/python3.11/site-packages/flask/app.py", line 1511, in wsgi_app
    response = self.full_dispatch_request()
               ^^^^^^^^^^^^^^^^^^^^^^^^^^^^
  File "/opt/app-root/lib64/python3.11/site-packages/flask/app.py", line 919, in full_dispatch_request
    rv = self.handle_user_exception(e)
         ^^^^^^^^^^^^^^^^^^^^^^^^^^^^^
  File "/opt/app-root/lib64/python3.11/site-packages/flask/app.py", line 917, in full_dispatch_request
    rv = self.dispatch_request()
         ^^^^^^^^^^^^^^^^^^^^^^^
  File "/opt/app-root/lib64/python3.11/site-packages/flask/app.py", line 902, in dispatch_request
    return self.ensure_sync(self.view_functions[rule.endpoint])(**view_args)  # type: ignore[no-any-return]
           ^^^^^^^^^^^^^^^^^^^^^^^^^^^^^^^^^^^^^^^^^^^^^^^^^^^^^^^^^^^^^^^^^
  File "/opt/app-root/src/app.py", line 99, in home
    categories = get_unique_categories()
                 ^^^^^^^^^^^^^^^^^^^^^^^
  File "/opt/app-root/src/app.py", line 71, in get_unique_categories
    categories = db.session.query(Article.category).distinct().all()
                 ^^^^^^^^^^^^^^^^^^^^^^^^^^^^^^^^^^^^^^^^^^^^^^^^^^^
  File "/opt/app-root/lib64/python3.11/site-packages/sqlalchemy/orm/query.py", line 2673, in all
    return self._iter().all()  # type: ignore
           ^^^^^^^^^^^^
  File "/opt/app-root/lib64/python3.11/site-packages/sqlalchemy/orm/query.py", line 2827, in _iter
    result: Union[ScalarResult[_T], Result[_T]] = self.session.execute(
                                                  ^^^^^^^^^^^^^^^^^^^^^
  File "/opt/app-root/lib64/python3.11/site-packages/sqlalchemy/orm/session.py", line 2362, in execute
    return self._execute_internal(
           ^^^^^^^^^^^^^^^^^^^^^^^
  File "/opt/app-root/lib64/python3.11/site-packages/sqlalchemy/orm/session.py", line 2247, in _execute_internal
    result: Result[Any] = compile_state_cls.orm_execute_statement(
                          ^^^^^^^^^^^^^^^^^^^^^^^^^^^^^^^^^^^^^^^^
  File "/opt/app-root/lib64/python3.11/site-packages/sqlalchemy/orm/context.py", line 305, in orm_execute_statement
    result = conn.execute(
             ^^^^^^^^^^^^^
  File "/opt/app-root/lib64/python3.11/site-packages/sqlalchemy/engine/base.py", line 1418, in execute
    return meth(
           ^^^^^
  File "/opt/app-root/lib64/python3.11/site-packages/sqlalchemy/sql/elements.py", line 515, in _execute_on_connection
    return connection._execute_clauseelement(
           ^^^^^^^^^^^^^^^^^^^^^^^^^^^^^^^^^^
  File "/opt/app-root/lib64/python3.11/site-packages/sqlalchemy/engine/base.py", line 1640, in _execute_clauseelement
    ret = self._execute_context(
          ^^^^^^^^^^^^^^^^^^^^^^
  File "/opt/app-root/lib64/python3.11/site-packages/sqlalchemy/engine/base.py", line 1846, in _execute_context
    return self._exec_single_context(
           ^^^^^^^^^^^^^^^^^^^^^^^^^^
  File "/opt/app-root/lib64/python3.11/site-packages/sqlalchemy/engine/base.py", line 1986, in _exec_single_context
    self._handle_dbapi_exception(
  File "/opt/app-root/lib64/python3.11/site-packages/sqlalchemy/engine/base.py", line 2355, in _handle_dbapi_exception
    raise sqlalchemy_exception.with_traceback(exc_info[2]) from e
  File "/opt/app-root/lib64/python3.11/site-packages/sqlalchemy/engine/base.py", line 1967, in _exec_single_context
    self.dialect.do_execute(
  File "/opt/app-root/lib64/python3.11/site-packages/sqlalchemy/engine/default.py", line 941, in do_execute
    cursor.execute(statement, parameters)
sqlalchemy.exc.OperationalError: (sqlite3.OperationalError) no such table: article
[SQL: SELECT DISTINCT article.category AS article_category 
FROM article]
(Background on this error at: https://sqlalche.me/e/20/e3q8)
10.128.0.2 - - [22/Dec/2024 23:30:12] "GET / HTTP/1.1" 500 -
[2024-12-22 23:30:32,938] ERROR in app: Exception on / [GET]
Traceback (most recent call last):
  File "/opt/app-root/lib64/python3.11/site-packages/sqlalchemy/engine/base.py", line 1967, in _exec_single_context
    self.dialect.do_execute(
  File "/opt/app-root/lib64/python3.11/site-packages/sqlalchemy/engine/default.py", line 941, in do_execute
    cursor.execute(statement, parameters)
sqlite3.OperationalError: no such table: article

The above exception was the direct cause of the following exception:

Traceback (most recent call last):
  File "/opt/app-root/lib64/python3.11/site-packages/flask/app.py", line 1511, in wsgi_app
    response = self.full_dispatch_request()
               ^^^^^^^^^^^^^^^^^^^^^^^^^^^^
  File "/opt/app-root/lib64/python3.11/site-packages/flask/app.py", line 919, in full_dispatch_request
    rv = self.handle_user_exception(e)
         ^^^^^^^^^^^^^^^^^^^^^^^^^^^^^
  File "/opt/app-root/lib64/python3.11/site-packages/flask/app.py", line 917, in full_dispatch_request
    rv = self.dispatch_request()
         ^^^^^^^^^^^^^^^^^^^^^^^
  File "/opt/app-root/lib64/python3.11/site-packages/flask/app.py", line 902, in dispatch_request
    return self.ensure_sync(self.view_functions[rule.endpoint])(**view_args)  # type: ignore[no-any-return]
           ^^^^^^^^^^^^^^^^^^^^^^^^^^^^^^^^^^^^^^^^^^^^^^^^^^^^^^^^^^^^^^^^^
  File "/opt/app-root/src/app.py", line 99, in home
    categories = get_unique_categories()
                 ^^^^^^^^^^^^^^^^^^^^^^^
  File "/opt/app-root/src/app.py", line 71, in get_unique_categories
    categories = db.session.query(Article.category).distinct().all()
                 ^^^^^^^^^^^^^^^^^^^^^^^^^^^^^^^^^^^^^^^^^^^^^^^^^^^
  File "/opt/app-root/lib64/python3.11/site-packages/sqlalchemy/orm/query.py", line 2673, in all
    return self._iter().all()  # type: ignore
           ^^^^^^^^^^^^
  File "/opt/app-root/lib64/python3.11/site-packages/sqlalchemy/orm/query.py", line 2827, in _iter
    result: Union[ScalarResult[_T], Result[_T]] = self.session.execute(
                                                  ^^^^^^^^^^^^^^^^^^^^^
  File "/opt/app-root/lib64/python3.11/site-packages/sqlalchemy/orm/session.py", line 2362, in execute
    return self._execute_internal(
           ^^^^^^^^^^^^^^^^^^^^^^^
  File "/opt/app-root/lib64/python3.11/site-packages/sqlalchemy/orm/session.py", line 2247, in _execute_internal
    result: Result[Any] = compile_state_cls.orm_execute_statement(
                          ^^^^^^^^^^^^^^^^^^^^^^^^^^^^^^^^^^^^^^^^
  File "/opt/app-root/lib64/python3.11/site-packages/sqlalchemy/orm/context.py", line 305, in orm_execute_statement
    result = conn.execute(
             ^^^^^^^^^^^^^
  File "/opt/app-root/lib64/python3.11/site-packages/sqlalchemy/engine/base.py", line 1418, in execute
    return meth(
           ^^^^^
  File "/opt/app-root/lib64/python3.11/site-packages/sqlalchemy/sql/elements.py", line 515, in _execute_on_connection
    return connection._execute_clauseelement(
           ^^^^^^^^^^^^^^^^^^^^^^^^^^^^^^^^^^
  File "/opt/app-root/lib64/python3.11/site-packages/sqlalchemy/engine/base.py", line 1640, in _execute_clauseelement
    ret = self._execute_context(
          ^^^^^^^^^^^^^^^^^^^^^^
  File "/opt/app-root/lib64/python3.11/site-packages/sqlalchemy/engine/base.py", line 1846, in _execute_context
    return self._exec_single_context(
           ^^^^^^^^^^^^^^^^^^^^^^^^^^
  File "/opt/app-root/lib64/python3.11/site-packages/sqlalchemy/engine/base.py", line 1986, in _exec_single_context
    self._handle_dbapi_exception(
  File "/opt/app-root/lib64/python3.11/site-packages/sqlalchemy/engine/base.py", line 2355, in _handle_dbapi_exception
    raise sqlalchemy_exception.with_traceback(exc_info[2]) from e
  File "/opt/app-root/lib64/python3.11/site-packages/sqlalchemy/engine/base.py", line 1967, in _exec_single_context
    self.dialect.do_execute(
  File "/opt/app-root/lib64/python3.11/site-packages/sqlalchemy/engine/default.py", line 941, in do_execute
    cursor.execute(statement, parameters)
sqlalchemy.exc.OperationalError: (sqlite3.OperationalError) no such table: article
[SQL: SELECT DISTINCT article.category AS article_category 
FROM article]
(Background on this error at: https://sqlalche.me/e/20/e3q8)
10.128.0.2 - - [22/Dec/2024 23:30:32] "GET / HTTP/1.1" 500 -
[2024-12-22 23:35:34,764] ERROR in app: Exception on / [GET]
Traceback (most recent call last):
  File "/opt/app-root/lib64/python3.11/site-packages/sqlalchemy/engine/base.py", line 1967, in _exec_single_context
    self.dialect.do_execute(
  File "/opt/app-root/lib64/python3.11/site-packages/sqlalchemy/engine/default.py", line 941, in do_execute
    cursor.execute(statement, parameters)
sqlite3.OperationalError: no such table: article

The above exception was the direct cause of the following exception:

Traceback (most recent call last):
  File "/opt/app-root/lib64/python3.11/site-packages/flask/app.py", line 1511, in wsgi_app
    response = self.full_dispatch_request()
               ^^^^^^^^^^^^^^^^^^^^^^^^^^^^
  File "/opt/app-root/lib64/python3.11/site-packages/flask/app.py", line 919, in full_dispatch_request
    rv = self.handle_user_exception(e)
         ^^^^^^^^^^^^^^^^^^^^^^^^^^^^^
  File "/opt/app-root/lib64/python3.11/site-packages/flask/app.py", line 917, in full_dispatch_request
    rv = self.dispatch_request()
         ^^^^^^^^^^^^^^^^^^^^^^^
  File "/opt/app-root/lib64/python3.11/site-packages/flask/app.py", line 902, in dispatch_request
    return self.ensure_sync(self.view_functions[rule.endpoint])(**view_args)  # type: ignore[no-any-return]
           ^^^^^^^^^^^^^^^^^^^^^^^^^^^^^^^^^^^^^^^^^^^^^^^^^^^^^^^^^^^^^^^^^
  File "/opt/app-root/src/app.py", line 99, in home
    categories = get_unique_categories()
                 ^^^^^^^^^^^^^^^^^^^^^^^
  File "/opt/app-root/src/app.py", line 71, in get_unique_categories
    categories = db.session.query(Article.category).distinct().all()
                 ^^^^^^^^^^^^^^^^^^^^^^^^^^^^^^^^^^^^^^^^^^^^^^^^^^^
  File "/opt/app-root/lib64/python3.11/site-packages/sqlalchemy/orm/query.py", line 2673, in all
    return self._iter().all()  # type: ignore
           ^^^^^^^^^^^^
  File "/opt/app-root/lib64/python3.11/site-packages/sqlalchemy/orm/query.py", line 2827, in _iter
    result: Union[ScalarResult[_T], Result[_T]] = self.session.execute(
                                                  ^^^^^^^^^^^^^^^^^^^^^
  File "/opt/app-root/lib64/python3.11/site-packages/sqlalchemy/orm/session.py", line 2362, in execute
    return self._execute_internal(
           ^^^^^^^^^^^^^^^^^^^^^^^
  File "/opt/app-root/lib64/python3.11/site-packages/sqlalchemy/orm/session.py", line 2247, in _execute_internal
    result: Result[Any] = compile_state_cls.orm_execute_statement(
                          ^^^^^^^^^^^^^^^^^^^^^^^^^^^^^^^^^^^^^^^^
  File "/opt/app-root/lib64/python3.11/site-packages/sqlalchemy/orm/context.py", line 305, in orm_execute_statement
    result = conn.execute(
             ^^^^^^^^^^^^^
  File "/opt/app-root/lib64/python3.11/site-packages/sqlalchemy/engine/base.py", line 1418, in execute
    return meth(
           ^^^^^
  File "/opt/app-root/lib64/python3.11/site-packages/sqlalchemy/sql/elements.py", line 515, in _execute_on_connection
    return connection._execute_clauseelement(
           ^^^^^^^^^^^^^^^^^^^^^^^^^^^^^^^^^^
  File "/opt/app-root/lib64/python3.11/site-packages/sqlalchemy/engine/base.py", line 1640, in _execute_clauseelement
    ret = self._execute_context(
          ^^^^^^^^^^^^^^^^^^^^^^
  File "/opt/app-root/lib64/python3.11/site-packages/sqlalchemy/engine/base.py", line 1846, in _execute_context
    return self._exec_single_context(
           ^^^^^^^^^^^^^^^^^^^^^^^^^^
  File "/opt/app-root/lib64/python3.11/site-packages/sqlalchemy/engine/base.py", line 1986, in _exec_single_context
    self._handle_dbapi_exception(
  File "/opt/app-root/lib64/python3.11/site-packages/sqlalchemy/engine/base.py", line 2355, in _handle_dbapi_exception
    raise sqlalchemy_exception.with_traceback(exc_info[2]) from e
  File "/opt/app-root/lib64/python3.11/site-packages/sqlalchemy/engine/base.py", line 1967, in _exec_single_context
    self.dialect.do_execute(
  File "/opt/app-root/lib64/python3.11/site-packages/sqlalchemy/engine/default.py", line 941, in do_execute
    cursor.execute(statement, parameters)
sqlalchemy.exc.OperationalError: (sqlite3.OperationalError) no such table: article
[SQL: SELECT DISTINCT article.category AS article_category 
FROM article]
(Background on this error at: https://sqlalche.me/e/20/e3q8)
10.128.0.2 - - [22/Dec/2024 23:35:34] "GET / HTTP/1.1" 500 -
[2024-12-22 23:39:01,052] ERROR in app: Exception on / [GET]
Traceback (most recent call last):
  File "/opt/app-root/lib64/python3.11/site-packages/sqlalchemy/engine/base.py", line 1967, in _exec_single_context
    self.dialect.do_execute(
  File "/opt/app-root/lib64/python3.11/site-packages/sqlalchemy/engine/default.py", line 941, in do_execute
    cursor.execute(statement, parameters)
sqlite3.OperationalError: no such table: article

The above exception was the direct cause of the following exception:

Traceback (most recent call last):
  File "/opt/app-root/lib64/python3.11/site-packages/flask/app.py", line 1511, in wsgi_app
    response = self.full_dispatch_request()
               ^^^^^^^^^^^^^^^^^^^^^^^^^^^^
  File "/opt/app-root/lib64/python3.11/site-packages/flask/app.py", line 919, in full_dispatch_request
    rv = self.handle_user_exception(e)
         ^^^^^^^^^^^^^^^^^^^^^^^^^^^^^
  File "/opt/app-root/lib64/python3.11/site-packages/flask/app.py", line 917, in full_dispatch_request
    rv = self.dispatch_request()
         ^^^^^^^^^^^^^^^^^^^^^^^
  File "/opt/app-root/lib64/python3.11/site-packages/flask/app.py", line 902, in dispatch_request
    return self.ensure_sync(self.view_functions[rule.endpoint])(**view_args)  # type: ignore[no-any-return]
           ^^^^^^^^^^^^^^^^^^^^^^^^^^^^^^^^^^^^^^^^^^^^^^^^^^^^^^^^^^^^^^^^^
  File "/opt/app-root/src/app.py", line 99, in home
    categories = get_unique_categories()
                 ^^^^^^^^^^^^^^^^^^^^^^^
  File "/opt/app-root/src/app.py", line 71, in get_unique_categories
    categories = db.session.query(Article.category).distinct().all()
                 ^^^^^^^^^^^^^^^^^^^^^^^^^^^^^^^^^^^^^^^^^^^^^^^^^^^
  File "/opt/app-root/lib64/python3.11/site-packages/sqlalchemy/orm/query.py", line 2673, in all
    return self._iter().all()  # type: ignore
           ^^^^^^^^^^^^
  File "/opt/app-root/lib64/python3.11/site-packages/sqlalchemy/orm/query.py", line 2827, in _iter
    result: Union[ScalarResult[_T], Result[_T]] = self.session.execute(
                                                  ^^^^^^^^^^^^^^^^^^^^^
  File "/opt/app-root/lib64/python3.11/site-packages/sqlalchemy/orm/session.py", line 2362, in execute
    return self._execute_internal(
           ^^^^^^^^^^^^^^^^^^^^^^^
  File "/opt/app-root/lib64/python3.11/site-packages/sqlalchemy/orm/session.py", line 2247, in _execute_internal
    result: Result[Any] = compile_state_cls.orm_execute_statement(
                          ^^^^^^^^^^^^^^^^^^^^^^^^^^^^^^^^^^^^^^^^
  File "/opt/app-root/lib64/python3.11/site-packages/sqlalchemy/orm/context.py", line 305, in orm_execute_statement
    result = conn.execute(
             ^^^^^^^^^^^^^
  File "/opt/app-root/lib64/python3.11/site-packages/sqlalchemy/engine/base.py", line 1418, in execute
    return meth(
           ^^^^^
  File "/opt/app-root/lib64/python3.11/site-packages/sqlalchemy/sql/elements.py", line 515, in _execute_on_connection
    return connection._execute_clauseelement(
           ^^^^^^^^^^^^^^^^^^^^^^^^^^^^^^^^^^
  File "/opt/app-root/lib64/python3.11/site-packages/sqlalchemy/engine/base.py", line 1640, in _execute_clauseelement
    ret = self._execute_context(
          ^^^^^^^^^^^^^^^^^^^^^^
  File "/opt/app-root/lib64/python3.11/site-packages/sqlalchemy/engine/base.py", line 1846, in _execute_context
    return self._exec_single_context(
           ^^^^^^^^^^^^^^^^^^^^^^^^^^
  File "/opt/app-root/lib64/python3.11/site-packages/sqlalchemy/engine/base.py", line 1986, in _exec_single_context
    self._handle_dbapi_exception(
  File "/opt/app-root/lib64/python3.11/site-packages/sqlalchemy/engine/base.py", line 2355, in _handle_dbapi_exception
    raise sqlalchemy_exception.with_traceback(exc_info[2]) from e
  File "/opt/app-root/lib64/python3.11/site-packages/sqlalchemy/engine/base.py", line 1967, in _exec_single_context
    self.dialect.do_execute(
  File "/opt/app-root/lib64/python3.11/site-packages/sqlalchemy/engine/default.py", line 941, in do_execute
    cursor.execute(statement, parameters)
sqlalchemy.exc.OperationalError: (sqlite3.OperationalError) no such table: article
[SQL: SELECT DISTINCT article.category AS article_category 
FROM article]
(Background on this error at: https://sqlalche.me/e/20/e3q8)
10.128.0.2 - - [22/Dec/2024 23:39:01] "GET / HTTP/1.1" 500 -
[2024-12-22 23:39:15,932] ERROR in app: Exception on / [GET]
Traceback (most recent call last):
  File "/opt/app-root/lib64/python3.11/site-packages/sqlalchemy/engine/base.py", line 1967, in _exec_single_context
    self.dialect.do_execute(
  File "/opt/app-root/lib64/python3.11/site-packages/sqlalchemy/engine/default.py", line 941, in do_execute
    cursor.execute(statement, parameters)
sqlite3.OperationalError: no such table: article

The above exception was the direct cause of the following exception:

Traceback (most recent call last):
  File "/opt/app-root/lib64/python3.11/site-packages/flask/app.py", line 1511, in wsgi_app
    response = self.full_dispatch_request()
               ^^^^^^^^^^^^^^^^^^^^^^^^^^^^
  File "/opt/app-root/lib64/python3.11/site-packages/flask/app.py", line 919, in full_dispatch_request
    rv = self.handle_user_exception(e)
         ^^^^^^^^^^^^^^^^^^^^^^^^^^^^^
  File "/opt/app-root/lib64/python3.11/site-packages/flask/app.py", line 917, in full_dispatch_request
    rv = self.dispatch_request()
         ^^^^^^^^^^^^^^^^^^^^^^^
  File "/opt/app-root/lib64/python3.11/site-packages/flask/app.py", line 902, in dispatch_request
    return self.ensure_sync(self.view_functions[rule.endpoint])(**view_args)  # type: ignore[no-any-return]
           ^^^^^^^^^^^^^^^^^^^^^^^^^^^^^^^^^^^^^^^^^^^^^^^^^^^^^^^^^^^^^^^^^
  File "/opt/app-root/src/app.py", line 99, in home
    categories = get_unique_categories()
                 ^^^^^^^^^^^^^^^^^^^^^^^
  File "/opt/app-root/src/app.py", line 71, in get_unique_categories
    categories = db.session.query(Article.category).distinct().all()
                 ^^^^^^^^^^^^^^^^^^^^^^^^^^^^^^^^^^^^^^^^^^^^^^^^^^^
  File "/opt/app-root/lib64/python3.11/site-packages/sqlalchemy/orm/query.py", line 2673, in all
    return self._iter().all()  # type: ignore
           ^^^^^^^^^^^^
  File "/opt/app-root/lib64/python3.11/site-packages/sqlalchemy/orm/query.py", line 2827, in _iter
    result: Union[ScalarResult[_T], Result[_T]] = self.session.execute(
                                                  ^^^^^^^^^^^^^^^^^^^^^
  File "/opt/app-root/lib64/python3.11/site-packages/sqlalchemy/orm/session.py", line 2362, in execute
    return self._execute_internal(
           ^^^^^^^^^^^^^^^^^^^^^^^
  File "/opt/app-root/lib64/python3.11/site-packages/sqlalchemy/orm/session.py", line 2247, in _execute_internal
    result: Result[Any] = compile_state_cls.orm_execute_statement(
                          ^^^^^^^^^^^^^^^^^^^^^^^^^^^^^^^^^^^^^^^^
  File "/opt/app-root/lib64/python3.11/site-packages/sqlalchemy/orm/context.py", line 305, in orm_execute_statement
    result = conn.execute(
             ^^^^^^^^^^^^^
  File "/opt/app-root/lib64/python3.11/site-packages/sqlalchemy/engine/base.py", line 1418, in execute
    return meth(
           ^^^^^
  File "/opt/app-root/lib64/python3.11/site-packages/sqlalchemy/sql/elements.py", line 515, in _execute_on_connection
    return connection._execute_clauseelement(
           ^^^^^^^^^^^^^^^^^^^^^^^^^^^^^^^^^^
  File "/opt/app-root/lib64/python3.11/site-packages/sqlalchemy/engine/base.py", line 1640, in _execute_clauseelement
    ret = self._execute_context(
          ^^^^^^^^^^^^^^^^^^^^^^
  File "/opt/app-root/lib64/python3.11/site-packages/sqlalchemy/engine/base.py", line 1846, in _execute_context
    return self._exec_single_context(
           ^^^^^^^^^^^^^^^^^^^^^^^^^^
  File "/opt/app-root/lib64/python3.11/site-packages/sqlalchemy/engine/base.py", line 1986, in _exec_single_context
    self._handle_dbapi_exception(
  File "/opt/app-root/lib64/python3.11/site-packages/sqlalchemy/engine/base.py", line 2355, in _handle_dbapi_exception
    raise sqlalchemy_exception.with_traceback(exc_info[2]) from e
  File "/opt/app-root/lib64/python3.11/site-packages/sqlalchemy/engine/base.py", line 1967, in _exec_single_context
    self.dialect.do_execute(
  File "/opt/app-root/lib64/python3.11/site-packages/sqlalchemy/engine/default.py", line 941, in do_execute
    cursor.execute(statement, parameters)
sqlalchemy.exc.OperationalError: (sqlite3.OperationalError) no such table: article
[SQL: SELECT DISTINCT article.category AS article_category 
FROM article]
(Background on this error at: https://sqlalche.me/e/20/e3q8)
10.128.0.2 - - [22/Dec/2024 23:39:15] "GET / HTTP/1.1" 500 -
[2024-12-22 23:53:32,991] ERROR in app: Exception on / [GET]
Traceback (most recent call last):
  File "/opt/app-root/lib64/python3.11/site-packages/sqlalchemy/engine/base.py", line 1967, in _exec_single_context
    self.dialect.do_execute(
  File "/opt/app-root/lib64/python3.11/site-packages/sqlalchemy/engine/default.py", line 941, in do_execute
    cursor.execute(statement, parameters)
sqlite3.OperationalError: no such table: article

The above exception was the direct cause of the following exception:

Traceback (most recent call last):
  File "/opt/app-root/lib64/python3.11/site-packages/flask/app.py", line 1511, in wsgi_app
    response = self.full_dispatch_request()
               ^^^^^^^^^^^^^^^^^^^^^^^^^^^^
  File "/opt/app-root/lib64/python3.11/site-packages/flask/app.py", line 919, in full_dispatch_request
    rv = self.handle_user_exception(e)
         ^^^^^^^^^^^^^^^^^^^^^^^^^^^^^
  File "/opt/app-root/lib64/python3.11/site-packages/flask/app.py", line 917, in full_dispatch_request
    rv = self.dispatch_request()
         ^^^^^^^^^^^^^^^^^^^^^^^
  File "/opt/app-root/lib64/python3.11/site-packages/flask/app.py", line 902, in dispatch_request
    return self.ensure_sync(self.view_functions[rule.endpoint])(**view_args)  # type: ignore[no-any-return]
           ^^^^^^^^^^^^^^^^^^^^^^^^^^^^^^^^^^^^^^^^^^^^^^^^^^^^^^^^^^^^^^^^^
  File "/opt/app-root/src/app.py", line 99, in home
    categories = get_unique_categories()
                 ^^^^^^^^^^^^^^^^^^^^^^^
  File "/opt/app-root/src/app.py", line 71, in get_unique_categories
    categories = db.session.query(Article.category).distinct().all()
                 ^^^^^^^^^^^^^^^^^^^^^^^^^^^^^^^^^^^^^^^^^^^^^^^^^^^
  File "/opt/app-root/lib64/python3.11/site-packages/sqlalchemy/orm/query.py", line 2673, in all
    return self._iter().all()  # type: ignore
           ^^^^^^^^^^^^
  File "/opt/app-root/lib64/python3.11/site-packages/sqlalchemy/orm/query.py", line 2827, in _iter
    result: Union[ScalarResult[_T], Result[_T]] = self.session.execute(
                                                  ^^^^^^^^^^^^^^^^^^^^^
  File "/opt/app-root/lib64/python3.11/site-packages/sqlalchemy/orm/session.py", line 2362, in execute
    return self._execute_internal(
           ^^^^^^^^^^^^^^^^^^^^^^^
  File "/opt/app-root/lib64/python3.11/site-packages/sqlalchemy/orm/session.py", line 2247, in _execute_internal
    result: Result[Any] = compile_state_cls.orm_execute_statement(
                          ^^^^^^^^^^^^^^^^^^^^^^^^^^^^^^^^^^^^^^^^
  File "/opt/app-root/lib64/python3.11/site-packages/sqlalchemy/orm/context.py", line 305, in orm_execute_statement
    result = conn.execute(
             ^^^^^^^^^^^^^
  File "/opt/app-root/lib64/python3.11/site-packages/sqlalchemy/engine/base.py", line 1418, in execute
    return meth(
           ^^^^^
  File "/opt/app-root/lib64/python3.11/site-packages/sqlalchemy/sql/elements.py", line 515, in _execute_on_connection
    return connection._execute_clauseelement(
           ^^^^^^^^^^^^^^^^^^^^^^^^^^^^^^^^^^
  File "/opt/app-root/lib64/python3.11/site-packages/sqlalchemy/engine/base.py", line 1640, in _execute_clauseelement
    ret = self._execute_context(
          ^^^^^^^^^^^^^^^^^^^^^^
  File "/opt/app-root/lib64/python3.11/site-packages/sqlalchemy/engine/base.py", line 1846, in _execute_context
    return self._exec_single_context(
           ^^^^^^^^^^^^^^^^^^^^^^^^^^
  File "/opt/app-root/lib64/python3.11/site-packages/sqlalchemy/engine/base.py", line 1986, in _exec_single_context
    self._handle_dbapi_exception(
  File "/opt/app-root/lib64/python3.11/site-packages/sqlalchemy/engine/base.py", line 2355, in _handle_dbapi_exception
    raise sqlalchemy_exception.with_traceback(exc_info[2]) from e
  File "/opt/app-root/lib64/python3.11/site-packages/sqlalchemy/engine/base.py", line 1967, in _exec_single_context
    self.dialect.do_execute(
  File "/opt/app-root/lib64/python3.11/site-packages/sqlalchemy/engine/default.py", line 941, in do_execute
    cursor.execute(statement, parameters)
sqlalchemy.exc.OperationalError: (sqlite3.OperationalError) no such table: article
[SQL: SELECT DISTINCT article.category AS article_category 
FROM article]
(Background on this error at: https://sqlalche.me/e/20/e3q8)
10.128.0.2 - - [22/Dec/2024 23:53:32] "GET / HTTP/1.1" 500 -
[2024-12-23 02:01:53,943] ERROR in app: Exception on / [GET]
Traceback (most recent call last):
  File "/opt/app-root/lib64/python3.11/site-packages/sqlalchemy/engine/base.py", line 1967, in _exec_single_context
    self.dialect.do_execute(
  File "/opt/app-root/lib64/python3.11/site-packages/sqlalchemy/engine/default.py", line 941, in do_execute
    cursor.execute(statement, parameters)
sqlite3.OperationalError: no such table: article

The above exception was the direct cause of the following exception:

Traceback (most recent call last):
  File "/opt/app-root/lib64/python3.11/site-packages/flask/app.py", line 1511, in wsgi_app
    response = self.full_dispatch_request()
               ^^^^^^^^^^^^^^^^^^^^^^^^^^^^
  File "/opt/app-root/lib64/python3.11/site-packages/flask/app.py", line 919, in full_dispatch_request
    rv = self.handle_user_exception(e)
         ^^^^^^^^^^^^^^^^^^^^^^^^^^^^^
  File "/opt/app-root/lib64/python3.11/site-packages/flask/app.py", line 917, in full_dispatch_request
    rv = self.dispatch_request()
         ^^^^^^^^^^^^^^^^^^^^^^^
  File "/opt/app-root/lib64/python3.11/site-packages/flask/app.py", line 902, in dispatch_request
    return self.ensure_sync(self.view_functions[rule.endpoint])(**view_args)  # type: ignore[no-any-return]
           ^^^^^^^^^^^^^^^^^^^^^^^^^^^^^^^^^^^^^^^^^^^^^^^^^^^^^^^^^^^^^^^^^
  File "/opt/app-root/src/app.py", line 99, in home
    categories = get_unique_categories()
                 ^^^^^^^^^^^^^^^^^^^^^^^
  File "/opt/app-root/src/app.py", line 71, in get_unique_categories
    categories = db.session.query(Article.category).distinct().all()
                 ^^^^^^^^^^^^^^^^^^^^^^^^^^^^^^^^^^^^^^^^^^^^^^^^^^^
  File "/opt/app-root/lib64/python3.11/site-packages/sqlalchemy/orm/query.py", line 2673, in all
    return self._iter().all()  # type: ignore
           ^^^^^^^^^^^^
  File "/opt/app-root/lib64/python3.11/site-packages/sqlalchemy/orm/query.py", line 2827, in _iter
    result: Union[ScalarResult[_T], Result[_T]] = self.session.execute(
                                                  ^^^^^^^^^^^^^^^^^^^^^
  File "/opt/app-root/lib64/python3.11/site-packages/sqlalchemy/orm/session.py", line 2362, in execute
    return self._execute_internal(
           ^^^^^^^^^^^^^^^^^^^^^^^
  File "/opt/app-root/lib64/python3.11/site-packages/sqlalchemy/orm/session.py", line 2247, in _execute_internal
    result: Result[Any] = compile_state_cls.orm_execute_statement(
                          ^^^^^^^^^^^^^^^^^^^^^^^^^^^^^^^^^^^^^^^^
  File "/opt/app-root/lib64/python3.11/site-packages/sqlalchemy/orm/context.py", line 305, in orm_execute_statement
    result = conn.execute(
             ^^^^^^^^^^^^^
  File "/opt/app-root/lib64/python3.11/site-packages/sqlalchemy/engine/base.py", line 1418, in execute
    return meth(
           ^^^^^
  File "/opt/app-root/lib64/python3.11/site-packages/sqlalchemy/sql/elements.py", line 515, in _execute_on_connection
    return connection._execute_clauseelement(
           ^^^^^^^^^^^^^^^^^^^^^^^^^^^^^^^^^^
  File "/opt/app-root/lib64/python3.11/site-packages/sqlalchemy/engine/base.py", line 1640, in _execute_clauseelement
    ret = self._execute_context(
          ^^^^^^^^^^^^^^^^^^^^^^
  File "/opt/app-root/lib64/python3.11/site-packages/sqlalchemy/engine/base.py", line 1846, in _execute_context
    return self._exec_single_context(
           ^^^^^^^^^^^^^^^^^^^^^^^^^^
  File "/opt/app-root/lib64/python3.11/site-packages/sqlalchemy/engine/base.py", line 1986, in _exec_single_context
    self._handle_dbapi_exception(
  File "/opt/app-root/lib64/python3.11/site-packages/sqlalchemy/engine/base.py", line 2355, in _handle_dbapi_exception
    raise sqlalchemy_exception.with_traceback(exc_info[2]) from e
  File "/opt/app-root/lib64/python3.11/site-packages/sqlalchemy/engine/base.py", line 1967, in _exec_single_context
    self.dialect.do_execute(
  File "/opt/app-root/lib64/python3.11/site-packages/sqlalchemy/engine/default.py", line 941, in do_execute
    cursor.execute(statement, parameters)
sqlalchemy.exc.OperationalError: (sqlite3.OperationalError) no such table: article
[SQL: SELECT DISTINCT article.category AS article_category 
FROM article]
(Background on this error at: https://sqlalche.me/e/20/e3q8)
10.128.0.2 - - [23/Dec/2024 02:01:53] "GET / HTTP/1.1" 500 -
10.128.0.2 - - [23/Dec/2024 02:01:54] "GET /favicon.ico HTTP/1.1" 404 -
[2024-12-23 02:08:03,774] ERROR in app: Exception on / [GET]
Traceback (most recent call last):
  File "/opt/app-root/lib64/python3.11/site-packages/sqlalchemy/engine/base.py", line 1967, in _exec_single_context
    self.dialect.do_execute(
  File "/opt/app-root/lib64/python3.11/site-packages/sqlalchemy/engine/default.py", line 941, in do_execute
    cursor.execute(statement, parameters)
sqlite3.OperationalError: no such table: article

The above exception was the direct cause of the following exception:

Traceback (most recent call last):
  File "/opt/app-root/lib64/python3.11/site-packages/flask/app.py", line 1511, in wsgi_app
    response = self.full_dispatch_request()
               ^^^^^^^^^^^^^^^^^^^^^^^^^^^^
  File "/opt/app-root/lib64/python3.11/site-packages/flask/app.py", line 919, in full_dispatch_request
    rv = self.handle_user_exception(e)
         ^^^^^^^^^^^^^^^^^^^^^^^^^^^^^
  File "/opt/app-root/lib64/python3.11/site-packages/flask/app.py", line 917, in full_dispatch_request
    rv = self.dispatch_request()
         ^^^^^^^^^^^^^^^^^^^^^^^
  File "/opt/app-root/lib64/python3.11/site-packages/flask/app.py", line 902, in dispatch_request
    return self.ensure_sync(self.view_functions[rule.endpoint])(**view_args)  # type: ignore[no-any-return]
           ^^^^^^^^^^^^^^^^^^^^^^^^^^^^^^^^^^^^^^^^^^^^^^^^^^^^^^^^^^^^^^^^^
  File "/opt/app-root/src/app.py", line 99, in home
    categories = get_unique_categories()
                 ^^^^^^^^^^^^^^^^^^^^^^^
  File "/opt/app-root/src/app.py", line 71, in get_unique_categories
    categories = db.session.query(Article.category).distinct().all()
                 ^^^^^^^^^^^^^^^^^^^^^^^^^^^^^^^^^^^^^^^^^^^^^^^^^^^
  File "/opt/app-root/lib64/python3.11/site-packages/sqlalchemy/orm/query.py", line 2673, in all
    return self._iter().all()  # type: ignore
           ^^^^^^^^^^^^
  File "/opt/app-root/lib64/python3.11/site-packages/sqlalchemy/orm/query.py", line 2827, in _iter
    result: Union[ScalarResult[_T], Result[_T]] = self.session.execute(
                                                  ^^^^^^^^^^^^^^^^^^^^^
  File "/opt/app-root/lib64/python3.11/site-packages/sqlalchemy/orm/session.py", line 2362, in execute
    return self._execute_internal(
           ^^^^^^^^^^^^^^^^^^^^^^^
  File "/opt/app-root/lib64/python3.11/site-packages/sqlalchemy/orm/session.py", line 2247, in _execute_internal
    result: Result[Any] = compile_state_cls.orm_execute_statement(
                          ^^^^^^^^^^^^^^^^^^^^^^^^^^^^^^^^^^^^^^^^
  File "/opt/app-root/lib64/python3.11/site-packages/sqlalchemy/orm/context.py", line 305, in orm_execute_statement
    result = conn.execute(
             ^^^^^^^^^^^^^
  File "/opt/app-root/lib64/python3.11/site-packages/sqlalchemy/engine/base.py", line 1418, in execute
    return meth(
           ^^^^^
  File "/opt/app-root/lib64/python3.11/site-packages/sqlalchemy/sql/elements.py", line 515, in _execute_on_connection
    return connection._execute_clauseelement(
           ^^^^^^^^^^^^^^^^^^^^^^^^^^^^^^^^^^
  File "/opt/app-root/lib64/python3.11/site-packages/sqlalchemy/engine/base.py", line 1640, in _execute_clauseelement
    ret = self._execute_context(
          ^^^^^^^^^^^^^^^^^^^^^^
  File "/opt/app-root/lib64/python3.11/site-packages/sqlalchemy/engine/base.py", line 1846, in _execute_context
    return self._exec_single_context(
           ^^^^^^^^^^^^^^^^^^^^^^^^^^
  File "/opt/app-root/lib64/python3.11/site-packages/sqlalchemy/engine/base.py", line 1986, in _exec_single_context
    self._handle_dbapi_exception(
  File "/opt/app-root/lib64/python3.11/site-packages/sqlalchemy/engine/base.py", line 2355, in _handle_dbapi_exception
    raise sqlalchemy_exception.with_traceback(exc_info[2]) from e
  File "/opt/app-root/lib64/python3.11/site-packages/sqlalchemy/engine/base.py", line 1967, in _exec_single_context
    self.dialect.do_execute(
  File "/opt/app-root/lib64/python3.11/site-packages/sqlalchemy/engine/default.py", line 941, in do_execute
    cursor.execute(statement, parameters)
sqlalchemy.exc.OperationalError: (sqlite3.OperationalError) no such table: article
[SQL: SELECT DISTINCT article.category AS article_category 
FROM article]
(Background on this error at: https://sqlalche.me/e/20/e3q8)
10.128.0.2 - - [23/Dec/2024 02:08:03] "GET / HTTP/1.1" 500 -
[2024-12-23 02:08:55,739] ERROR in app: Exception on / [GET]
Traceback (most recent call last):
  File "/opt/app-root/lib64/python3.11/site-packages/sqlalchemy/engine/base.py", line 1967, in _exec_single_context
    self.dialect.do_execute(
  File "/opt/app-root/lib64/python3.11/site-packages/sqlalchemy/engine/default.py", line 941, in do_execute
    cursor.execute(statement, parameters)
sqlite3.OperationalError: no such table: article

The above exception was the direct cause of the following exception:

Traceback (most recent call last):
  File "/opt/app-root/lib64/python3.11/site-packages/flask/app.py", line 1511, in wsgi_app
    response = self.full_dispatch_request()
               ^^^^^^^^^^^^^^^^^^^^^^^^^^^^
  File "/opt/app-root/lib64/python3.11/site-packages/flask/app.py", line 919, in full_dispatch_request
    rv = self.handle_user_exception(e)
         ^^^^^^^^^^^^^^^^^^^^^^^^^^^^^
  File "/opt/app-root/lib64/python3.11/site-packages/flask/app.py", line 917, in full_dispatch_request
    rv = self.dispatch_request()
         ^^^^^^^^^^^^^^^^^^^^^^^
  File "/opt/app-root/lib64/python3.11/site-packages/flask/app.py", line 902, in dispatch_request
    return self.ensure_sync(self.view_functions[rule.endpoint])(**view_args)  # type: ignore[no-any-return]
           ^^^^^^^^^^^^^^^^^^^^^^^^^^^^^^^^^^^^^^^^^^^^^^^^^^^^^^^^^^^^^^^^^
  File "/opt/app-root/src/app.py", line 99, in home
    categories = get_unique_categories()
                 ^^^^^^^^^^^^^^^^^^^^^^^
  File "/opt/app-root/src/app.py", line 71, in get_unique_categories
    categories = db.session.query(Article.category).distinct().all()
                 ^^^^^^^^^^^^^^^^^^^^^^^^^^^^^^^^^^^^^^^^^^^^^^^^^^^
  File "/opt/app-root/lib64/python3.11/site-packages/sqlalchemy/orm/query.py", line 2673, in all
    return self._iter().all()  # type: ignore
           ^^^^^^^^^^^^
  File "/opt/app-root/lib64/python3.11/site-packages/sqlalchemy/orm/query.py", line 2827, in _iter
    result: Union[ScalarResult[_T], Result[_T]] = self.session.execute(
                                                  ^^^^^^^^^^^^^^^^^^^^^
  File "/opt/app-root/lib64/python3.11/site-packages/sqlalchemy/orm/session.py", line 2362, in execute
    return self._execute_internal(
           ^^^^^^^^^^^^^^^^^^^^^^^
  File "/opt/app-root/lib64/python3.11/site-packages/sqlalchemy/orm/session.py", line 2247, in _execute_internal
    result: Result[Any] = compile_state_cls.orm_execute_statement(
                          ^^^^^^^^^^^^^^^^^^^^^^^^^^^^^^^^^^^^^^^^
  File "/opt/app-root/lib64/python3.11/site-packages/sqlalchemy/orm/context.py", line 305, in orm_execute_statement
    result = conn.execute(
             ^^^^^^^^^^^^^
  File "/opt/app-root/lib64/python3.11/site-packages/sqlalchemy/engine/base.py", line 1418, in execute
    return meth(
           ^^^^^
  File "/opt/app-root/lib64/python3.11/site-packages/sqlalchemy/sql/elements.py", line 515, in _execute_on_connection
    return connection._execute_clauseelement(
           ^^^^^^^^^^^^^^^^^^^^^^^^^^^^^^^^^^
  File "/opt/app-root/lib64/python3.11/site-packages/sqlalchemy/engine/base.py", line 1640, in _execute_clauseelement
    ret = self._execute_context(
          ^^^^^^^^^^^^^^^^^^^^^^
  File "/opt/app-root/lib64/python3.11/site-packages/sqlalchemy/engine/base.py", line 1846, in _execute_context
    return self._exec_single_context(
           ^^^^^^^^^^^^^^^^^^^^^^^^^^
  File "/opt/app-root/lib64/python3.11/site-packages/sqlalchemy/engine/base.py", line 1986, in _exec_single_context
    self._handle_dbapi_exception(
  File "/opt/app-root/lib64/python3.11/site-packages/sqlalchemy/engine/base.py", line 2355, in _handle_dbapi_exception
    raise sqlalchemy_exception.with_traceback(exc_info[2]) from e
  File "/opt/app-root/lib64/python3.11/site-packages/sqlalchemy/engine/base.py", line 1967, in _exec_single_context
    self.dialect.do_execute(
  File "/opt/app-root/lib64/python3.11/site-packages/sqlalchemy/engine/default.py", line 941, in do_execute
    cursor.execute(statement, parameters)
sqlalchemy.exc.OperationalError: (sqlite3.OperationalError) no such table: article
[SQL: SELECT DISTINCT article.category AS article_category 
FROM article]
(Background on this error at: https://sqlalche.me/e/20/e3q8)
10.128.0.2 - - [23/Dec/2024 02:08:55] "GET / HTTP/1.1" 500 -
[2024-12-23 02:10:11,989] ERROR in app: Exception on / [GET]
Traceback (most recent call last):
  File "/opt/app-root/lib64/python3.11/site-packages/sqlalchemy/engine/base.py", line 1967, in _exec_single_context
    self.dialect.do_execute(
  File "/opt/app-root/lib64/python3.11/site-packages/sqlalchemy/engine/default.py", line 941, in do_execute
    cursor.execute(statement, parameters)
sqlite3.OperationalError: no such table: article

The above exception was the direct cause of the following exception:

Traceback (most recent call last):
  File "/opt/app-root/lib64/python3.11/site-packages/flask/app.py", line 1511, in wsgi_app
    response = self.full_dispatch_request()
               ^^^^^^^^^^^^^^^^^^^^^^^^^^^^
  File "/opt/app-root/lib64/python3.11/site-packages/flask/app.py", line 919, in full_dispatch_request
    rv = self.handle_user_exception(e)
         ^^^^^^^^^^^^^^^^^^^^^^^^^^^^^
  File "/opt/app-root/lib64/python3.11/site-packages/flask/app.py", line 917, in full_dispatch_request
    rv = self.dispatch_request()
         ^^^^^^^^^^^^^^^^^^^^^^^
  File "/opt/app-root/lib64/python3.11/site-packages/flask/app.py", line 902, in dispatch_request
    return self.ensure_sync(self.view_functions[rule.endpoint])(**view_args)  # type: ignore[no-any-return]
           ^^^^^^^^^^^^^^^^^^^^^^^^^^^^^^^^^^^^^^^^^^^^^^^^^^^^^^^^^^^^^^^^^
  File "/opt/app-root/src/app.py", line 99, in home
    categories = get_unique_categories()
                 ^^^^^^^^^^^^^^^^^^^^^^^
  File "/opt/app-root/src/app.py", line 71, in get_unique_categories
    categories = db.session.query(Article.category).distinct().all()
                 ^^^^^^^^^^^^^^^^^^^^^^^^^^^^^^^^^^^^^^^^^^^^^^^^^^^
  File "/opt/app-root/lib64/python3.11/site-packages/sqlalchemy/orm/query.py", line 2673, in all
    return self._iter().all()  # type: ignore
           ^^^^^^^^^^^^
  File "/opt/app-root/lib64/python3.11/site-packages/sqlalchemy/orm/query.py", line 2827, in _iter
    result: Union[ScalarResult[_T], Result[_T]] = self.session.execute(
                                                  ^^^^^^^^^^^^^^^^^^^^^
  File "/opt/app-root/lib64/python3.11/site-packages/sqlalchemy/orm/session.py", line 2362, in execute
    return self._execute_internal(
           ^^^^^^^^^^^^^^^^^^^^^^^
  File "/opt/app-root/lib64/python3.11/site-packages/sqlalchemy/orm/session.py", line 2247, in _execute_internal
    result: Result[Any] = compile_state_cls.orm_execute_statement(
                          ^^^^^^^^^^^^^^^^^^^^^^^^^^^^^^^^^^^^^^^^
  File "/opt/app-root/lib64/python3.11/site-packages/sqlalchemy/orm/context.py", line 305, in orm_execute_statement
    result = conn.execute(
             ^^^^^^^^^^^^^
  File "/opt/app-root/lib64/python3.11/site-packages/sqlalchemy/engine/base.py", line 1418, in execute
    return meth(
           ^^^^^
  File "/opt/app-root/lib64/python3.11/site-packages/sqlalchemy/sql/elements.py", line 515, in _execute_on_connection
    return connection._execute_clauseelement(
           ^^^^^^^^^^^^^^^^^^^^^^^^^^^^^^^^^^
  File "/opt/app-root/lib64/python3.11/site-packages/sqlalchemy/engine/base.py", line 1640, in _execute_clauseelement
    ret = self._execute_context(
          ^^^^^^^^^^^^^^^^^^^^^^
  File "/opt/app-root/lib64/python3.11/site-packages/sqlalchemy/engine/base.py", line 1846, in _execute_context
    return self._exec_single_context(
           ^^^^^^^^^^^^^^^^^^^^^^^^^^
  File "/opt/app-root/lib64/python3.11/site-packages/sqlalchemy/engine/base.py", line 1986, in _exec_single_context
    self._handle_dbapi_exception(
  File "/opt/app-root/lib64/python3.11/site-packages/sqlalchemy/engine/base.py", line 2355, in _handle_dbapi_exception
    raise sqlalchemy_exception.with_traceback(exc_info[2]) from e
  File "/opt/app-root/lib64/python3.11/site-packages/sqlalchemy/engine/base.py", line 1967, in _exec_single_context
    self.dialect.do_execute(
  File "/opt/app-root/lib64/python3.11/site-packages/sqlalchemy/engine/default.py", line 941, in do_execute
    cursor.execute(statement, parameters)
sqlalchemy.exc.OperationalError: (sqlite3.OperationalError) no such table: article
[SQL: SELECT DISTINCT article.category AS article_category 
FROM article]
(Background on this error at: https://sqlalche.me/e/20/e3q8)
10.128.0.2 - - [23/Dec/2024 02:10:11] "GET / HTTP/1.1" 500 -
[2024-12-23 02:32:57,588] ERROR in app: Exception on / [GET]
Traceback (most recent call last):
  File "/opt/app-root/lib64/python3.11/site-packages/sqlalchemy/engine/base.py", line 1967, in _exec_single_context
    self.dialect.do_execute(
  File "/opt/app-root/lib64/python3.11/site-packages/sqlalchemy/engine/default.py", line 941, in do_execute
    cursor.execute(statement, parameters)
sqlite3.OperationalError: no such table: article

The above exception was the direct cause of the following exception:

Traceback (most recent call last):
  File "/opt/app-root/lib64/python3.11/site-packages/flask/app.py", line 1511, in wsgi_app
    response = self.full_dispatch_request()
               ^^^^^^^^^^^^^^^^^^^^^^^^^^^^
  File "/opt/app-root/lib64/python3.11/site-packages/flask/app.py", line 919, in full_dispatch_request
    rv = self.handle_user_exception(e)
         ^^^^^^^^^^^^^^^^^^^^^^^^^^^^^
  File "/opt/app-root/lib64/python3.11/site-packages/flask/app.py", line 917, in full_dispatch_request
    rv = self.dispatch_request()
         ^^^^^^^^^^^^^^^^^^^^^^^
  File "/opt/app-root/lib64/python3.11/site-packages/flask/app.py", line 902, in dispatch_request
    return self.ensure_sync(self.view_functions[rule.endpoint])(**view_args)  # type: ignore[no-any-return]
           ^^^^^^^^^^^^^^^^^^^^^^^^^^^^^^^^^^^^^^^^^^^^^^^^^^^^^^^^^^^^^^^^^
  File "/opt/app-root/src/app.py", line 99, in home
    categories = get_unique_categories()
                 ^^^^^^^^^^^^^^^^^^^^^^^
  File "/opt/app-root/src/app.py", line 71, in get_unique_categories
    categories = db.session.query(Article.category).distinct().all()
                 ^^^^^^^^^^^^^^^^^^^^^^^^^^^^^^^^^^^^^^^^^^^^^^^^^^^
  File "/opt/app-root/lib64/python3.11/site-packages/sqlalchemy/orm/query.py", line 2673, in all
    return self._iter().all()  # type: ignore
           ^^^^^^^^^^^^
  File "/opt/app-root/lib64/python3.11/site-packages/sqlalchemy/orm/query.py", line 2827, in _iter
    result: Union[ScalarResult[_T], Result[_T]] = self.session.execute(
                                                  ^^^^^^^^^^^^^^^^^^^^^
  File "/opt/app-root/lib64/python3.11/site-packages/sqlalchemy/orm/session.py", line 2362, in execute
    return self._execute_internal(
           ^^^^^^^^^^^^^^^^^^^^^^^
  File "/opt/app-root/lib64/python3.11/site-packages/sqlalchemy/orm/session.py", line 2247, in _execute_internal
    result: Result[Any] = compile_state_cls.orm_execute_statement(
                          ^^^^^^^^^^^^^^^^^^^^^^^^^^^^^^^^^^^^^^^^
  File "/opt/app-root/lib64/python3.11/site-packages/sqlalchemy/orm/context.py", line 305, in orm_execute_statement
    result = conn.execute(
             ^^^^^^^^^^^^^
  File "/opt/app-root/lib64/python3.11/site-packages/sqlalchemy/engine/base.py", line 1418, in execute
    return meth(
           ^^^^^
  File "/opt/app-root/lib64/python3.11/site-packages/sqlalchemy/sql/elements.py", line 515, in _execute_on_connection
    return connection._execute_clauseelement(
           ^^^^^^^^^^^^^^^^^^^^^^^^^^^^^^^^^^
  File "/opt/app-root/lib64/python3.11/site-packages/sqlalchemy/engine/base.py", line 1640, in _execute_clauseelement
    ret = self._execute_context(
          ^^^^^^^^^^^^^^^^^^^^^^
  File "/opt/app-root/lib64/python3.11/site-packages/sqlalchemy/engine/base.py", line 1846, in _execute_context
    return self._exec_single_context(
           ^^^^^^^^^^^^^^^^^^^^^^^^^^
  File "/opt/app-root/lib64/python3.11/site-packages/sqlalchemy/engine/base.py", line 1986, in _exec_single_context
    self._handle_dbapi_exception(
  File "/opt/app-root/lib64/python3.11/site-packages/sqlalchemy/engine/base.py", line 2355, in _handle_dbapi_exception
    raise sqlalchemy_exception.with_traceback(exc_info[2]) from e
  File "/opt/app-root/lib64/python3.11/site-packages/sqlalchemy/engine/base.py", line 1967, in _exec_single_context
    self.dialect.do_execute(
  File "/opt/app-root/lib64/python3.11/site-packages/sqlalchemy/engine/default.py", line 941, in do_execute
    cursor.execute(statement, parameters)
sqlalchemy.exc.OperationalError: (sqlite3.OperationalError) no such table: article
[SQL: SELECT DISTINCT article.category AS article_category 
FROM article]
(Background on this error at: https://sqlalche.me/e/20/e3q8)
10.128.0.2 - - [23/Dec/2024 02:32:57] "GET / HTTP/1.1" 500 -
[2024-12-23 02:37:20,232] ERROR in app: Exception on / [GET]
Traceback (most recent call last):
  File "/opt/app-root/lib64/python3.11/site-packages/sqlalchemy/engine/base.py", line 1967, in _exec_single_context
    self.dialect.do_execute(
  File "/opt/app-root/lib64/python3.11/site-packages/sqlalchemy/engine/default.py", line 941, in do_execute
    cursor.execute(statement, parameters)
sqlite3.OperationalError: no such table: article

The above exception was the direct cause of the following exception:

Traceback (most recent call last):
  File "/opt/app-root/lib64/python3.11/site-packages/flask/app.py", line 1511, in wsgi_app
    response = self.full_dispatch_request()
               ^^^^^^^^^^^^^^^^^^^^^^^^^^^^
  File "/opt/app-root/lib64/python3.11/site-packages/flask/app.py", line 919, in full_dispatch_request
    rv = self.handle_user_exception(e)
         ^^^^^^^^^^^^^^^^^^^^^^^^^^^^^
  File "/opt/app-root/lib64/python3.11/site-packages/flask/app.py", line 917, in full_dispatch_request
    rv = self.dispatch_request()
         ^^^^^^^^^^^^^^^^^^^^^^^
  File "/opt/app-root/lib64/python3.11/site-packages/flask/app.py", line 902, in dispatch_request
    return self.ensure_sync(self.view_functions[rule.endpoint])(**view_args)  # type: ignore[no-any-return]
           ^^^^^^^^^^^^^^^^^^^^^^^^^^^^^^^^^^^^^^^^^^^^^^^^^^^^^^^^^^^^^^^^^
  File "/opt/app-root/src/app.py", line 99, in home
    categories = get_unique_categories()
                 ^^^^^^^^^^^^^^^^^^^^^^^
  File "/opt/app-root/src/app.py", line 71, in get_unique_categories
    categories = db.session.query(Article.category).distinct().all()
                 ^^^^^^^^^^^^^^^^^^^^^^^^^^^^^^^^^^^^^^^^^^^^^^^^^^^
  File "/opt/app-root/lib64/python3.11/site-packages/sqlalchemy/orm/query.py", line 2673, in all
    return self._iter().all()  # type: ignore
           ^^^^^^^^^^^^
  File "/opt/app-root/lib64/python3.11/site-packages/sqlalchemy/orm/query.py", line 2827, in _iter
    result: Union[ScalarResult[_T], Result[_T]] = self.session.execute(
                                                  ^^^^^^^^^^^^^^^^^^^^^
  File "/opt/app-root/lib64/python3.11/site-packages/sqlalchemy/orm/session.py", line 2362, in execute
    return self._execute_internal(
           ^^^^^^^^^^^^^^^^^^^^^^^
  File "/opt/app-root/lib64/python3.11/site-packages/sqlalchemy/orm/session.py", line 2247, in _execute_internal
    result: Result[Any] = compile_state_cls.orm_execute_statement(
                          ^^^^^^^^^^^^^^^^^^^^^^^^^^^^^^^^^^^^^^^^
  File "/opt/app-root/lib64/python3.11/site-packages/sqlalchemy/orm/context.py", line 305, in orm_execute_statement
    result = conn.execute(
             ^^^^^^^^^^^^^
  File "/opt/app-root/lib64/python3.11/site-packages/sqlalchemy/engine/base.py", line 1418, in execute
    return meth(
           ^^^^^
  File "/opt/app-root/lib64/python3.11/site-packages/sqlalchemy/sql/elements.py", line 515, in _execute_on_connection
    return connection._execute_clauseelement(
           ^^^^^^^^^^^^^^^^^^^^^^^^^^^^^^^^^^
  File "/opt/app-root/lib64/python3.11/site-packages/sqlalchemy/engine/base.py", line 1640, in _execute_clauseelement
    ret = self._execute_context(
          ^^^^^^^^^^^^^^^^^^^^^^
  File "/opt/app-root/lib64/python3.11/site-packages/sqlalchemy/engine/base.py", line 1846, in _execute_context
    return self._exec_single_context(
           ^^^^^^^^^^^^^^^^^^^^^^^^^^
  File "/opt/app-root/lib64/python3.11/site-packages/sqlalchemy/engine/base.py", line 1986, in _exec_single_context
    self._handle_dbapi_exception(
  File "/opt/app-root/lib64/python3.11/site-packages/sqlalchemy/engine/base.py", line 2355, in _handle_dbapi_exception
    raise sqlalchemy_exception.with_traceback(exc_info[2]) from e
  File "/opt/app-root/lib64/python3.11/site-packages/sqlalchemy/engine/base.py", line 1967, in _exec_single_context
    self.dialect.do_execute(
  File "/opt/app-root/lib64/python3.11/site-packages/sqlalchemy/engine/default.py", line 941, in do_execute
    cursor.execute(statement, parameters)
sqlalchemy.exc.OperationalError: (sqlite3.OperationalError) no such table: article
[SQL: SELECT DISTINCT article.category AS article_category 
FROM article]
(Background on this error at: https://sqlalche.me/e/20/e3q8)
10.128.0.2 - - [23/Dec/2024 02:37:20] "GET / HTTP/1.1" 500 -
[2024-12-23 02:37:21,688] ERROR in app: Exception on / [GET]
Traceback (most recent call last):
  File "/opt/app-root/lib64/python3.11/site-packages/sqlalchemy/engine/base.py", line 1967, in _exec_single_context
    self.dialect.do_execute(
  File "/opt/app-root/lib64/python3.11/site-packages/sqlalchemy/engine/default.py", line 941, in do_execute
    cursor.execute(statement, parameters)
sqlite3.OperationalError: no such table: article

The above exception was the direct cause of the following exception:

Traceback (most recent call last):
  File "/opt/app-root/lib64/python3.11/site-packages/flask/app.py", line 1511, in wsgi_app
    response = self.full_dispatch_request()
               ^^^^^^^^^^^^^^^^^^^^^^^^^^^^
  File "/opt/app-root/lib64/python3.11/site-packages/flask/app.py", line 919, in full_dispatch_request
    rv = self.handle_user_exception(e)
         ^^^^^^^^^^^^^^^^^^^^^^^^^^^^^
  File "/opt/app-root/lib64/python3.11/site-packages/flask/app.py", line 917, in full_dispatch_request
    rv = self.dispatch_request()
         ^^^^^^^^^^^^^^^^^^^^^^^
  File "/opt/app-root/lib64/python3.11/site-packages/flask/app.py", line 902, in dispatch_request
    return self.ensure_sync(self.view_functions[rule.endpoint])(**view_args)  # type: ignore[no-any-return]
           ^^^^^^^^^^^^^^^^^^^^^^^^^^^^^^^^^^^^^^^^^^^^^^^^^^^^^^^^^^^^^^^^^
  File "/opt/app-root/src/app.py", line 99, in home
    categories = get_unique_categories()
                 ^^^^^^^^^^^^^^^^^^^^^^^
  File "/opt/app-root/src/app.py", line 71, in get_unique_categories
    categories = db.session.query(Article.category).distinct().all()
                 ^^^^^^^^^^^^^^^^^^^^^^^^^^^^^^^^^^^^^^^^^^^^^^^^^^^
  File "/opt/app-root/lib64/python3.11/site-packages/sqlalchemy/orm/query.py", line 2673, in all
    return self._iter().all()  # type: ignore
           ^^^^^^^^^^^^
  File "/opt/app-root/lib64/python3.11/site-packages/sqlalchemy/orm/query.py", line 2827, in _iter
    result: Union[ScalarResult[_T], Result[_T]] = self.session.execute(
                                                  ^^^^^^^^^^^^^^^^^^^^^
  File "/opt/app-root/lib64/python3.11/site-packages/sqlalchemy/orm/session.py", line 2362, in execute
    return self._execute_internal(
           ^^^^^^^^^^^^^^^^^^^^^^^
  File "/opt/app-root/lib64/python3.11/site-packages/sqlalchemy/orm/session.py", line 2247, in _execute_internal
    result: Result[Any] = compile_state_cls.orm_execute_statement(
                          ^^^^^^^^^^^^^^^^^^^^^^^^^^^^^^^^^^^^^^^^
  File "/opt/app-root/lib64/python3.11/site-packages/sqlalchemy/orm/context.py", line 305, in orm_execute_statement
    result = conn.execute(
             ^^^^^^^^^^^^^
  File "/opt/app-root/lib64/python3.11/site-packages/sqlalchemy/engine/base.py", line 1418, in execute
    return meth(
           ^^^^^
  File "/opt/app-root/lib64/python3.11/site-packages/sqlalchemy/sql/elements.py", line 515, in _execute_on_connection
    return connection._execute_clauseelement(
           ^^^^^^^^^^^^^^^^^^^^^^^^^^^^^^^^^^
  File "/opt/app-root/lib64/python3.11/site-packages/sqlalchemy/engine/base.py", line 1640, in _execute_clauseelement
    ret = self._execute_context(
          ^^^^^^^^^^^^^^^^^^^^^^
  File "/opt/app-root/lib64/python3.11/site-packages/sqlalchemy/engine/base.py", line 1846, in _execute_context
    return self._exec_single_context(
           ^^^^^^^^^^^^^^^^^^^^^^^^^^
  File "/opt/app-root/lib64/python3.11/site-packages/sqlalchemy/engine/base.py", line 1986, in _exec_single_context
    self._handle_dbapi_exception(
  File "/opt/app-root/lib64/python3.11/site-packages/sqlalchemy/engine/base.py", line 2355, in _handle_dbapi_exception
    raise sqlalchemy_exception.with_traceback(exc_info[2]) from e
  File "/opt/app-root/lib64/python3.11/site-packages/sqlalchemy/engine/base.py", line 1967, in _exec_single_context
    self.dialect.do_execute(
  File "/opt/app-root/lib64/python3.11/site-packages/sqlalchemy/engine/default.py", line 941, in do_execute
    cursor.execute(statement, parameters)
sqlalchemy.exc.OperationalError: (sqlite3.OperationalError) no such table: article
[SQL: SELECT DISTINCT article.category AS article_category 
FROM article]
(Background on this error at: https://sqlalche.me/e/20/e3q8)
10.128.0.2 - - [23/Dec/2024 02:37:21] "GET / HTTP/1.1" 500 -
